[2019-Feb-08 17:21] 127.0.0.1 POST http http://localhost:5000/ 5xx INTERNAL SERVER ERROR
Traceback (most recent call last):
  File "/usr/local/lib/python3.5/dist-packages/flask/app.py", line 1813, in full_dispatch_request
    rv = self.dispatch_request()
  File "/usr/local/lib/python3.5/dist-packages/flask/app.py", line 1799, in dispatch_request
    return self.view_functions[rule.endpoint](**req.view_args)
  File "main.py", line 40, in index
    return render_template('index.html', error=error)
  File "/usr/local/lib/python3.5/dist-packages/flask/templating.py", line 135, in render_template
    context, ctx.app)
  File "/usr/local/lib/python3.5/dist-packages/flask/templating.py", line 117, in _render
    rv = template.render(context)
  File "/usr/local/lib/python3.5/dist-packages/jinja2/environment.py", line 1008, in render
    return self.environment.handle_exception(exc_info, True)
  File "/usr/local/lib/python3.5/dist-packages/jinja2/environment.py", line 780, in handle_exception
    reraise(exc_type, exc_value, tb)
  File "/usr/local/lib/python3.5/dist-packages/jinja2/_compat.py", line 37, in reraise
    raise value.with_traceback(tb)
  File "/mnt/d/Documents/computerScience/programming/python/ccdcCrypto/exchange/templates/index.html", line 1, in top-level template code
    {% extends "header.html" %}
  File "/mnt/d/Documents/computerScience/programming/python/ccdcCrypto/exchange/templates/header.html", line 29, in top-level template code
    <a href="{{ url_for('account') + session.username }}">Account</a>
  File "/usr/local/lib/python3.5/dist-packages/flask/helpers.py", line 356, in url_for
    return appctx.app.handle_url_build_error(error, endpoint, values)
  File "/usr/local/lib/python3.5/dist-packages/flask/app.py", line 2061, in handle_url_build_error
    reraise(exc_type, exc_value, tb)
  File "/usr/local/lib/python3.5/dist-packages/flask/_compat.py", line 35, in reraise
    raise value
  File "/usr/local/lib/python3.5/dist-packages/flask/helpers.py", line 345, in url_for
    force_external=external)
  File "/usr/local/lib/python3.5/dist-packages/werkzeug/routing.py", line 1776, in build
    raise BuildError(endpoint, values, method, self)
werkzeug.routing.BuildError: Could not build url for endpoint 'account'. Did you forget to specify values ['username']?

[2019-Feb-08 17:22] 127.0.0.1 POST http http://localhost:5000/ 200 OK ImmutableMultiDict([('password', 'r00M#Gb4p%ur'), ('username', 'dyl_up')])
[2019-Feb-08 17:22] 127.0.0.1 GET http http://localhost:5000/account/dyl_up 200 OK 
[2019-Feb-08 17:22] 127.0.0.1 GET http http://localhost:5000/ 200 OK 
[2019-Feb-08 17:22] 127.0.0.1 GET http http://localhost:5000/ 200 OK 
[2019-Feb-08 17:38] 127.0.0.1 GET http http://localhost:5000/ 200 OK 
[2019-Feb-08 17:38] 127.0.0.1 GET http http://localhost:5000/account/dyl_up 5xx INTERNAL SERVER ERROR
Traceback (most recent call last):
  File "/usr/local/lib/python3.5/dist-packages/flask/app.py", line 1813, in full_dispatch_request
    rv = self.dispatch_request()
  File "/usr/local/lib/python3.5/dist-packages/flask/app.py", line 1799, in dispatch_request
    return self.view_functions[rule.endpoint](**req.view_args)
  File "main.py", line 44, in account
    print(rpc.ammountReceivedPerAddress(username))
  File "/mnt/d/Documents/computerScience/programming/python/ccdcCrypto/exchange/dakRPC.py", line 24, in ammountReceivedPerAddress
    addrAmt = self.rpc.listreceivedbyaddress(account)
  File "/usr/local/lib/python3.5/dist-packages/bitcoinrpc/authproxy.py", line 136, in __call__
    'Content-type': 'application/json'})
  File "/usr/lib/python3.5/http/client.py", line 1106, in request
    self._send_request(method, url, body, headers)
  File "/usr/lib/python3.5/http/client.py", line 1151, in _send_request
    self.endheaders(body)
  File "/usr/lib/python3.5/http/client.py", line 1102, in endheaders
    self._send_output(message_body)
  File "/usr/lib/python3.5/http/client.py", line 934, in _send_output
    self.send(msg)
  File "/usr/lib/python3.5/http/client.py", line 877, in send
    self.connect()
  File "/usr/lib/python3.5/http/client.py", line 849, in connect
    (self.host,self.port), self.timeout, self.source_address)
  File "/usr/lib/python3.5/socket.py", line 711, in create_connection
    raise err
  File "/usr/lib/python3.5/socket.py", line 702, in create_connection
    sock.connect(sa)
ConnectionRefusedError: [Errno 111] Connection refused

[2019-Feb-08 17:40] 127.0.0.1 GET http http://localhost:5000/account/dyl_up 5xx INTERNAL SERVER ERROR
Traceback (most recent call last):
  File "/usr/local/lib/python3.5/dist-packages/flask/app.py", line 1813, in full_dispatch_request
    rv = self.dispatch_request()
  File "/usr/local/lib/python3.5/dist-packages/flask/app.py", line 1799, in dispatch_request
    return self.view_functions[rule.endpoint](**req.view_args)
  File "main.py", line 44, in account
    print(rpc.ammountReceivedPerAddress(username))
  File "/mnt/d/Documents/computerScience/programming/python/ccdcCrypto/exchange/dakRPC.py", line 24, in ammountReceivedPerAddress
    addrAmt = self.rpc.listreceivedbyaddress(account)
  File "/usr/local/lib/python3.5/dist-packages/bitcoinrpc/authproxy.py", line 139, in __call__
    response = self._get_response()
  File "/usr/local/lib/python3.5/dist-packages/bitcoinrpc/authproxy.py", line 187, in _get_response
    'code': -342, 'message': 'non-JSON HTTP response with \'%i %s\' from server' % (http_response.status, http_response.reason)})
bitcoinrpc.authproxy.JSONRPCException: -342: non-JSON HTTP response with '401 Authorization Required' from server

[2019-Feb-08 17:40] 127.0.0.1 GET http http://localhost:5000/logout 302 FOUND 
[2019-Feb-08 17:40] 127.0.0.1 GET http http://localhost:5000/ 200 OK 
[2019-Feb-08 17:40] 127.0.0.1 POST http http://localhost:5000/ 200 OK ImmutableMultiDict([('username', 'dyl_up'), ('password', 'r00M#Gb4p%ur')])
[2019-Feb-08 17:40] 127.0.0.1 GET http http://localhost:5000/account/dyl_up 5xx INTERNAL SERVER ERROR
Traceback (most recent call last):
  File "/usr/local/lib/python3.5/dist-packages/flask/app.py", line 1813, in full_dispatch_request
    rv = self.dispatch_request()
  File "/usr/local/lib/python3.5/dist-packages/flask/app.py", line 1799, in dispatch_request
    return self.view_functions[rule.endpoint](**req.view_args)
  File "main.py", line 44, in account
    print(rpc.ammountReceivedPerAddress(username))
  File "/mnt/d/Documents/computerScience/programming/python/ccdcCrypto/exchange/dakRPC.py", line 24, in ammountReceivedPerAddress
    addrAmt = self.rpc.listreceivedbyaddress(account)
  File "/usr/local/lib/python3.5/dist-packages/bitcoinrpc/authproxy.py", line 139, in __call__
    response = self._get_response()
  File "/usr/local/lib/python3.5/dist-packages/bitcoinrpc/authproxy.py", line 187, in _get_response
    'code': -342, 'message': 'non-JSON HTTP response with \'%i %s\' from server' % (http_response.status, http_response.reason)})
bitcoinrpc.authproxy.JSONRPCException: -342: non-JSON HTTP response with '401 Authorization Required' from server

[2019-Feb-11 12:23] 127.0.0.1 GET http http://localhost:5000/ 200 OK 
[2019-Feb-11 12:23] 127.0.0.1 GET http http://localhost:5000/static/styles/main.css 200 OK 
[2019-Feb-11 12:23] 127.0.0.1 GET http http://localhost:5000/account/dyl_up 5xx INTERNAL SERVER ERROR
Traceback (most recent call last):
  File "/usr/local/lib/python3.5/dist-packages/flask/app.py", line 1813, in full_dispatch_request
    rv = self.dispatch_request()
  File "/usr/local/lib/python3.5/dist-packages/flask/app.py", line 1799, in dispatch_request
    return self.view_functions[rule.endpoint](**req.view_args)
  File "main.py", line 44, in account
    print(rpc.ammountReceivedPerAddress(username))
  File "/mnt/d/Documents/computerScience/programming/python/ccdcCrypto/exchange/dakRPC.py", line 24, in ammountReceivedPerAddress
    addrAmt = self.rpc.listreceivedbyaddress(account)
  File "/usr/local/lib/python3.5/dist-packages/bitcoinrpc/authproxy.py", line 139, in __call__
    response = self._get_response()
  File "/usr/local/lib/python3.5/dist-packages/bitcoinrpc/authproxy.py", line 187, in _get_response
    'code': -342, 'message': 'non-JSON HTTP response with \'%i %s\' from server' % (http_response.status, http_response.reason)})
bitcoinrpc.authproxy.JSONRPCException: -342: non-JSON HTTP response with '401 Authorization Required' from server

[2019-Feb-11 12:23] 127.0.0.1 GET http http://localhost:5000/account/dyl_up 5xx INTERNAL SERVER ERROR
Traceback (most recent call last):
  File "/usr/local/lib/python3.5/dist-packages/flask/app.py", line 1813, in full_dispatch_request
    rv = self.dispatch_request()
  File "/usr/local/lib/python3.5/dist-packages/flask/app.py", line 1799, in dispatch_request
    return self.view_functions[rule.endpoint](**req.view_args)
  File "main.py", line 44, in account
    print(rpc.ammountReceivedPerAddress(username))
  File "/mnt/d/Documents/computerScience/programming/python/ccdcCrypto/exchange/dakRPC.py", line 24, in ammountReceivedPerAddress
    addrAmt = self.rpc.listreceivedbyaddress(account)
  File "/usr/local/lib/python3.5/dist-packages/bitcoinrpc/authproxy.py", line 139, in __call__
    response = self._get_response()
  File "/usr/local/lib/python3.5/dist-packages/bitcoinrpc/authproxy.py", line 179, in _get_response
    http_response = self.__conn.getresponse()
  File "/usr/lib/python3.5/http/client.py", line 1197, in getresponse
    response.begin()
  File "/usr/lib/python3.5/http/client.py", line 297, in begin
    version, status, reason = self._read_status()
  File "/usr/lib/python3.5/http/client.py", line 266, in _read_status
    raise RemoteDisconnected("Remote end closed connection without"
http.client.RemoteDisconnected: Remote end closed connection without response

[2019-Feb-11 12:23] 127.0.0.1 GET http http://localhost:5000/ 200 OK 
[2019-Feb-11 12:24] 127.0.0.1 GET http http://localhost:5000/account/dyl_up 5xx INTERNAL SERVER ERROR
Traceback (most recent call last):
  File "/usr/local/lib/python3.5/dist-packages/flask/app.py", line 1813, in full_dispatch_request
    rv = self.dispatch_request()
  File "/usr/local/lib/python3.5/dist-packages/flask/app.py", line 1799, in dispatch_request
    return self.view_functions[rule.endpoint](**req.view_args)
  File "main.py", line 44, in account
    print(rpc.ammountReceivedPerAddress(username))
  File "/mnt/d/Documents/computerScience/programming/python/ccdcCrypto/exchange/dakRPC.py", line 24, in ammountReceivedPerAddress
    addrAmt = self.rpc.listreceivedbyaddress(account)
  File "/usr/local/lib/python3.5/dist-packages/bitcoinrpc/authproxy.py", line 139, in __call__
    response = self._get_response()
  File "/usr/local/lib/python3.5/dist-packages/bitcoinrpc/authproxy.py", line 179, in _get_response
    http_response = self.__conn.getresponse()
  File "/usr/lib/python3.5/http/client.py", line 1197, in getresponse
    response.begin()
  File "/usr/lib/python3.5/http/client.py", line 297, in begin
    version, status, reason = self._read_status()
  File "/usr/lib/python3.5/http/client.py", line 266, in _read_status
    raise RemoteDisconnected("Remote end closed connection without"
http.client.RemoteDisconnected: Remote end closed connection without response

[2019-Feb-11 12:25] 127.0.0.1 GET http http://localhost:5000/account/dyl_up 5xx INTERNAL SERVER ERROR
Traceback (most recent call last):
  File "/usr/local/lib/python3.5/dist-packages/flask/app.py", line 1813, in full_dispatch_request
    rv = self.dispatch_request()
  File "/usr/local/lib/python3.5/dist-packages/flask/app.py", line 1799, in dispatch_request
    return self.view_functions[rule.endpoint](**req.view_args)
  File "main.py", line 44, in account
    print(rpc.ammountReceivedPerAddress(username))
  File "/mnt/d/Documents/computerScience/programming/python/ccdcCrypto/exchange/dakRPC.py", line 24, in ammountReceivedPerAddress
    addrAmt = self.rpc.listreceivedbyaddress(account)
  File "/usr/local/lib/python3.5/dist-packages/bitcoinrpc/authproxy.py", line 139, in __call__
    response = self._get_response()
  File "/usr/local/lib/python3.5/dist-packages/bitcoinrpc/authproxy.py", line 179, in _get_response
    http_response = self.__conn.getresponse()
  File "/usr/lib/python3.5/http/client.py", line 1197, in getresponse
    response.begin()
  File "/usr/lib/python3.5/http/client.py", line 297, in begin
    version, status, reason = self._read_status()
  File "/usr/lib/python3.5/http/client.py", line 266, in _read_status
    raise RemoteDisconnected("Remote end closed connection without"
http.client.RemoteDisconnected: Remote end closed connection without response

[2019-Feb-11 12:56] 127.0.0.1 GET http http://localhost:5000/account/dyl_up 5xx INTERNAL SERVER ERROR
Traceback (most recent call last):
  File "/usr/local/lib/python3.5/dist-packages/flask/app.py", line 1813, in full_dispatch_request
    rv = self.dispatch_request()
  File "/usr/local/lib/python3.5/dist-packages/flask/app.py", line 1799, in dispatch_request
    return self.view_functions[rule.endpoint](**req.view_args)
  File "main.py", line 44, in account
    print(rpc.ammountReceivedPerAddress(username))
  File "/mnt/d/Documents/computerScience/programming/python/ccdcCrypto/exchange/dakRPC.py", line 24, in ammountReceivedPerAddress
    addrAmt = self.rpc.listreceivedbyaddress(account)
  File "/usr/local/lib/python3.5/dist-packages/bitcoinrpc/authproxy.py", line 141, in __call__
    raise JSONRPCException(response['error'])
bitcoinrpc.authproxy.JSONRPCException: -1: value is type str, expected int

[2019-Feb-11 12:59] 127.0.0.1 GET http http://localhost:5000/account/dyl_up 5xx INTERNAL SERVER ERROR
Traceback (most recent call last):
  File "/usr/local/lib/python3.5/dist-packages/flask/app.py", line 1813, in full_dispatch_request
    rv = self.dispatch_request()
  File "/usr/local/lib/python3.5/dist-packages/flask/app.py", line 1799, in dispatch_request
    return self.view_functions[rule.endpoint](**req.view_args)
  File "main.py", line 44, in account
    print(rpc.ammountReceivedPerAddress(username))
  File "/mnt/d/Documents/computerScience/programming/python/ccdcCrypto/exchange/dakRPC.py", line 24, in ammountReceivedPerAddress
    addrAmt = self.rpc.listreceivedbyaddress(account)
  File "/usr/local/lib/python3.5/dist-packages/bitcoinrpc/authproxy.py", line 142, in __call__
    raise JSONRPCException(response['error'])
bitcoinrpc.authproxy.JSONRPCException: -1: value is type str, expected int

[2019-Feb-11 13:01] 127.0.0.1 GET http http://localhost:5000/account/test2 5xx INTERNAL SERVER ERROR
Traceback (most recent call last):
  File "/usr/local/lib/python3.5/dist-packages/flask/app.py", line 1813, in full_dispatch_request
    rv = self.dispatch_request()
  File "/usr/local/lib/python3.5/dist-packages/flask/app.py", line 1799, in dispatch_request
    return self.view_functions[rule.endpoint](**req.view_args)
  File "main.py", line 44, in account
    print(rpc.ammountReceivedPerAddress(username))
  File "/mnt/d/Documents/computerScience/programming/python/ccdcCrypto/exchange/dakRPC.py", line 24, in ammountReceivedPerAddress
    addrAmt = self.rpc.listreceivedbyaddress(account)
  File "/usr/local/lib/python3.5/dist-packages/bitcoinrpc/authproxy.py", line 142, in __call__
    raise JSONRPCException(response['error'])
bitcoinrpc.authproxy.JSONRPCException: -1: value is type str, expected int

[2019-Feb-11 13:02] 127.0.0.1 GET http http://localhost:5000/account/test2 5xx INTERNAL SERVER ERROR
Traceback (most recent call last):
  File "/usr/local/lib/python3.5/dist-packages/flask/app.py", line 1813, in full_dispatch_request
    rv = self.dispatch_request()
  File "/usr/local/lib/python3.5/dist-packages/flask/app.py", line 1799, in dispatch_request
    return self.view_functions[rule.endpoint](**req.view_args)
  File "main.py", line 44, in account
    print(rpc.ammountReceivedPerAddress(username))
  File "/mnt/d/Documents/computerScience/programming/python/ccdcCrypto/exchange/dakRPC.py", line 24, in ammountReceivedPerAddress
    addrAmt = self.rpc.listreceivedbyaddress(account)
  File "/usr/local/lib/python3.5/dist-packages/bitcoinrpc/authproxy.py", line 142, in __call__
    raise JSONRPCException(response['error'])
bitcoinrpc.authproxy.JSONRPCException: -1: value is type str, expected int

[2019-Feb-11 13:09] 127.0.0.1 GET http http://localhost:5000/account/test2 5xx INTERNAL SERVER ERROR
Traceback (most recent call last):
  File "/usr/local/lib/python3.5/dist-packages/flask/app.py", line 1813, in full_dispatch_request
    rv = self.dispatch_request()
  File "/usr/local/lib/python3.5/dist-packages/flask/app.py", line 1799, in dispatch_request
    return self.view_functions[rule.endpoint](**req.view_args)
  File "main.py", line 44, in account
    print(rpc.ammountReceivedPerAddress(username))
  File "/mnt/d/Documents/computerScience/programming/python/ccdcCrypto/exchange/dakRPC.py", line 26, in ammountReceivedPerAddress
    addrAmounts['addr'] = self.rpc.listreceivedbyaddress(addr)
  File "/usr/local/lib/python3.5/dist-packages/bitcoinrpc/authproxy.py", line 142, in __call__
    raise JSONRPCException(response['error'])
bitcoinrpc.authproxy.JSONRPCException: -1: value is type str, expected int

[2019-Feb-11 13:09] 127.0.0.1 GET http http://localhost:5000/account/test2 5xx INTERNAL SERVER ERROR
Traceback (most recent call last):
  File "/usr/local/lib/python3.5/dist-packages/flask/app.py", line 1813, in full_dispatch_request
    rv = self.dispatch_request()
  File "/usr/local/lib/python3.5/dist-packages/flask/app.py", line 1799, in dispatch_request
    return self.view_functions[rule.endpoint](**req.view_args)
  File "main.py", line 44, in account
    print(rpc.ammountReceivedPerAddress(username))
  File "/mnt/d/Documents/computerScience/programming/python/ccdcCrypto/exchange/dakRPC.py", line 27, in ammountReceivedPerAddress
    addrAmounts['addr'] = self.rpc.listreceivedbyaddress(addr)
  File "/usr/local/lib/python3.5/dist-packages/bitcoinrpc/authproxy.py", line 142, in __call__
    raise JSONRPCException(response['error'])
bitcoinrpc.authproxy.JSONRPCException: -1: value is type str, expected int

[2019-Feb-11 13:11] 127.0.0.1 GET http http://localhost:5000/account/test2 200 OK 
[2019-Feb-11 13:12] 127.0.0.1 GET http http://localhost:5000/account/test2 200 OK 
[2019-Feb-11 13:12] 127.0.0.1 GET http http://localhost:5000/account/test2 200 OK 
[2019-Feb-11 13:13] 127.0.0.1 GET http http://localhost:5000/account/test2 200 OK 
[2019-Feb-11 13:19] 127.0.0.1 GET http http://localhost:5000/account/test2 5xx INTERNAL SERVER ERROR
Traceback (most recent call last):
  File "/usr/local/lib/python3.5/dist-packages/flask/app.py", line 1813, in full_dispatch_request
    rv = self.dispatch_request()
  File "/usr/local/lib/python3.5/dist-packages/flask/app.py", line 1799, in dispatch_request
    return self.view_functions[rule.endpoint](**req.view_args)
  File "main.py", line 45, in account
    pprint(rpc.ammountReceivedPerAddress(username))
AttributeError: 'dakRpc' object has no attribute 'ammountReceivedPerAddress'

[2019-Feb-11 13:19] 127.0.0.1 GET http http://localhost:5000/account/test2 5xx INTERNAL SERVER ERROR
Traceback (most recent call last):
  File "/usr/local/lib/python3.5/dist-packages/flask/app.py", line 1813, in full_dispatch_request
    rv = self.dispatch_request()
  File "/usr/local/lib/python3.5/dist-packages/flask/app.py", line 1799, in dispatch_request
    return self.view_functions[rule.endpoint](**req.view_args)
  File "main.py", line 45, in account
    pprint(rpc.ammountReceivedByAddress(username))
AttributeError: 'dakRpc' object has no attribute 'ammountReceivedByAddress'

[2019-Feb-11 13:20] 127.0.0.1 GET http http://localhost:5000/account/test2 5xx INTERNAL SERVER ERROR
Traceback (most recent call last):
  File "/usr/local/lib/python3.5/dist-packages/flask/app.py", line 1813, in full_dispatch_request
    rv = self.dispatch_request()
  File "/usr/local/lib/python3.5/dist-packages/flask/app.py", line 1799, in dispatch_request
    return self.view_functions[rule.endpoint](**req.view_args)
  File "main.py", line 45, in account
    pprint(rpc.ammountReceivedByAccount(username))
AttributeError: 'dakRpc' object has no attribute 'ammountReceivedByAccount'

[2019-Feb-11 13:21] 127.0.0.1 GET http http://localhost:5000/account/test2 200 OK 
[2019-Feb-11 13:23] 127.0.0.1 GET http http://localhost:5000/ 5xx INTERNAL SERVER ERROR
Traceback (most recent call last):
  File "/usr/local/lib/python3.5/dist-packages/flask/app.py", line 1813, in full_dispatch_request
    rv = self.dispatch_request()
  File "/usr/local/lib/python3.5/dist-packages/flask/app.py", line 1799, in dispatch_request
    return self.view_functions[rule.endpoint](**req.view_args)
  File "main.py", line 40, in index
    return render_template('index.html', **userInfo)
  File "main.py", line 152, in <lambda>
    render_template = lambda *args, **kwargs: render_template(*args, rpc=rpc, **kwargs)
  File "main.py", line 152, in <lambda>
    render_template = lambda *args, **kwargs: render_template(*args, rpc=rpc, **kwargs)
TypeError: <lambda>() got multiple values for keyword argument 'rpc'

[2019-Feb-11 13:24] 127.0.0.1 GET http http://localhost:5000/ 5xx INTERNAL SERVER ERROR
Traceback (most recent call last):
  File "/usr/local/lib/python3.5/dist-packages/flask/app.py", line 1813, in full_dispatch_request
    rv = self.dispatch_request()
  File "/usr/local/lib/python3.5/dist-packages/flask/app.py", line 1799, in dispatch_request
    return self.view_functions[rule.endpoint](**req.view_args)
  File "main.py", line 40, in index
    return render_template('index.html', **userInfo)
  File "main.py", line 152, in <lambda>
    render_template = lambda *args, **kwargs: render_template(*args, **kwargs, rpc=rpc)
  File "main.py", line 152, in <lambda>
    render_template = lambda *args, **kwargs: render_template(*args, **kwargs, rpc=rpc)
TypeError: <lambda>() got multiple values for keyword argument 'rpc'

[2019-Feb-11 13:26] 127.0.0.1 GET http http://localhost:5000/ 200 OK 
[2019-Feb-11 13:26] 127.0.0.1 GET http http://localhost:5000/logout 302 FOUND 
[2019-Feb-11 13:26] 127.0.0.1 GET http http://localhost:5000/ 200 OK 
[2019-Feb-11 13:26] 127.0.0.1 POST http http://localhost:5000/register 200 OK ImmutableMultiDict([('password', 'r00M#Gb4p%ur'), ('username', 'dyl_up')])
[2019-Feb-11 13:27] 127.0.0.1 POST http http://localhost:5000/register 302 FOUND ImmutableMultiDict([('NewPassword', 'UvT$yRs8PfO8'), ('NewUsername', 'test2'), ('email', 'dsaf@dsaf.com')])
[2019-Feb-11 13:27] 127.0.0.1 GET http http://localhost:5000/account/test2?rpc=<dakRPC.dakRpc+object+at+0x7f027d0b06a0> 200 OK 
[2019-Feb-11 13:27] 127.0.0.1 GET http http://localhost:5000/favicon.ico 5xx INTERNAL SERVER ERROR
Traceback (most recent call last):
  File "/usr/local/lib/python3.5/dist-packages/flask/app.py", line 1813, in full_dispatch_request
    rv = self.dispatch_request()
  File "/usr/local/lib/python3.5/dist-packages/flask/app.py", line 1791, in dispatch_request
    self.raise_routing_exception(req)
  File "/usr/local/lib/python3.5/dist-packages/flask/app.py", line 1774, in raise_routing_exception
    raise request.routing_exception
  File "/usr/local/lib/python3.5/dist-packages/flask/ctx.py", line 336, in match_request
    self.url_adapter.match(return_rule=True)
  File "/usr/local/lib/python3.5/dist-packages/werkzeug/routing.py", line 1581, in match
    raise NotFound()
werkzeug.exceptions.NotFound: 404 Not Found: The requested URL was not found on the server.  If you entered the URL manually please check your spelling and try again.

[2019-Feb-11 13:27] 127.0.0.1 GET http http://localhost:5000/ 200 OK 
[2019-Feb-12 13:27] 127.0.0.1 GET http http://localhost:5000/ 200 OK 
[2019-Feb-12 13:27] 127.0.0.1 GET http http://localhost:5000/static/styles/main.css 304 NOT MODIFIED 
[2019-Feb-12 13:28] 127.0.0.1 POST http http://localhost:5000/register 5xx INTERNAL SERVER ERROR
Traceback (most recent call last):
  File "/usr/local/lib/python3.5/dist-packages/flask/app.py", line 1813, in full_dispatch_request
    rv = self.dispatch_request()
  File "/usr/local/lib/python3.5/dist-packages/flask/app.py", line 1799, in dispatch_request
    return self.view_functions[rule.endpoint](**req.view_args)
  File "main.py", line 92, in register
    username = request.form['NewUsername']
  File "/usr/local/lib/python3.5/dist-packages/werkzeug/datastructures.py", line 431, in __getitem__
    raise exceptions.BadRequestKeyError(key)
werkzeug.exceptions.HTTPException.wrap.<locals>.newcls: 400 Bad Request: KeyError: 'NewUsername'

[2019-Feb-12 13:29] 127.0.0.1 POST http http://localhost:5000/register 5xx INTERNAL SERVER ERROR
Traceback (most recent call last):
  File "/usr/local/lib/python3.5/dist-packages/flask/app.py", line 1813, in full_dispatch_request
    rv = self.dispatch_request()
  File "/usr/local/lib/python3.5/dist-packages/flask/app.py", line 1799, in dispatch_request
    return self.view_functions[rule.endpoint](**req.view_args)
  File "main.py", line 92, in register
    username = request.form['NewUsername']
  File "/usr/local/lib/python3.5/dist-packages/werkzeug/datastructures.py", line 431, in __getitem__
    raise exceptions.BadRequestKeyError(key)
werkzeug.exceptions.HTTPException.wrap.<locals>.newcls: 400 Bad Request: KeyError: 'NewUsername'

[2019-Feb-12 13:29] 127.0.0.1 POST http http://localhost:5000/register 5xx INTERNAL SERVER ERROR
Traceback (most recent call last):
  File "/usr/local/lib/python3.5/dist-packages/flask/app.py", line 1813, in full_dispatch_request
    rv = self.dispatch_request()
  File "/usr/local/lib/python3.5/dist-packages/flask/app.py", line 1799, in dispatch_request
    return self.view_functions[rule.endpoint](**req.view_args)
  File "main.py", line 92, in register
    if 'email' in request.form:
  File "/usr/local/lib/python3.5/dist-packages/werkzeug/datastructures.py", line 431, in __getitem__
    raise exceptions.BadRequestKeyError(key)
werkzeug.exceptions.HTTPException.wrap.<locals>.newcls: 400 Bad Request: KeyError: 'NewUsername'

[2019-Feb-12 13:31] 127.0.0.1 POST http http://localhost:5000/register 5xx INTERNAL SERVER ERROR
Traceback (most recent call last):
  File "/usr/local/lib/python3.5/dist-packages/flask/app.py", line 1813, in full_dispatch_request
    rv = self.dispatch_request()
  File "/usr/local/lib/python3.5/dist-packages/flask/app.py", line 1799, in dispatch_request
    return self.view_functions[rule.endpoint](**req.view_args)
  File "main.py", line 92, in register
    pprint(request.form)
  File "/usr/local/lib/python3.5/dist-packages/werkzeug/datastructures.py", line 431, in __getitem__
    raise exceptions.BadRequestKeyError(key)
werkzeug.exceptions.HTTPException.wrap.<locals>.newcls: 400 Bad Request: KeyError: 'NewUsername'

[2019-Feb-12 13:32] 127.0.0.1 GET http http://localhost:5000/ 200 OK 
[2019-Feb-12 13:32] 127.0.0.1 GET http http://localhost:5000/register 200 OK 
[2019-Feb-12 13:32] 127.0.0.1 POST http http://localhost:5000/register 5xx INTERNAL SERVER ERROR
Traceback (most recent call last):
  File "/usr/local/lib/python3.5/dist-packages/flask/app.py", line 1813, in full_dispatch_request
    rv = self.dispatch_request()
  File "/usr/local/lib/python3.5/dist-packages/flask/app.py", line 1799, in dispatch_request
    return self.view_functions[rule.endpoint](**req.view_args)
  File "main.py", line 92, in register
    print(request.form)
  File "/usr/local/lib/python3.5/dist-packages/werkzeug/datastructures.py", line 431, in __getitem__
    raise exceptions.BadRequestKeyError(key)
werkzeug.exceptions.HTTPException.wrap.<locals>.newcls: 400 Bad Request: KeyError: 'NewUsername'

[2019-Feb-12 13:33] 127.0.0.1 POST http http://localhost:5000/register 200 OK ImmutableMultiDict([('password', 'Password1!'), ('username', 'Administrator')])
[2019-Feb-12 13:33] 127.0.0.1 POST http http://localhost:5000/register 200 OK ImmutableMultiDict([('password', 'Password1!'), ('username', 'Administrator')])
[2019-Feb-12 13:33] 127.0.0.1 POST http http://localhost:5000/register 200 OK ImmutableMultiDict([('password', 'Password1!'), ('username', 'Administrator')])
[2019-Feb-12 13:34] 127.0.0.1 POST http http://localhost:5000/register 200 OK ImmutableMultiDict([('username', 'Administrator'), ('password', 'Password1!')])
